<?xml version="1.0" encoding="UTF-8"?>
<!-- Generated by org.testng.reporters.JUnitReportReporter -->
<testsuite hostname="welcome-PC" failures="0" tests="2" name="com.TestNG_TDD.expectedexcep" time="0.010" errors="2" timestamp="2021-03-22T20:16:53 IST" skipped="0">
  <testcase classname="com.TestNG_TDD.expectedexcep" name="demo1" time="0.001">
    <error message="
Expected exception of type class java.lang.NullPointerException but got java.lang.ArithmeticException: / by zero" type="org.testng.TestException">
      <![CDATA[org.testng.TestException: 
Expected exception of type class java.lang.NullPointerException but got java.lang.ArithmeticException: / by zero
at org.testng.internal.ExpectedExceptionsHolder.wrongException(ExpectedExceptionsHolder.java:68)
at org.testng.internal.TestInvoker.considerExceptions(TestInvoker.java:737)
at org.testng.internal.TestInvoker.invokeMethod(TestInvoker.java:635)
at org.testng.internal.TestInvoker.invokeTestMethod(TestInvoker.java:174)
at org.testng.internal.MethodRunner.runInSequence(MethodRunner.java:46)
at org.testng.internal.TestInvoker$MethodInvocationAgent.invoke(TestInvoker.java:822)
at org.testng.internal.TestInvoker.invokeTestMethods(TestInvoker.java:147)
at org.testng.internal.TestMethodWorker.invokeTestMethods(TestMethodWorker.java:146)
at org.testng.internal.TestMethodWorker.run(TestMethodWorker.java:128)
at java.base/java.util.ArrayList.forEach(ArrayList.java:1511)
at org.testng.TestRunner.privateRun(TestRunner.java:764)
at org.testng.TestRunner.run(TestRunner.java:585)
at org.testng.SuiteRunner.runTest(SuiteRunner.java:384)
at org.testng.SuiteRunner.runSequentially(SuiteRunner.java:378)
at org.testng.SuiteRunner.privateRun(SuiteRunner.java:337)
at org.testng.SuiteRunner.run(SuiteRunner.java:286)
at org.testng.SuiteRunnerWorker.runSuite(SuiteRunnerWorker.java:53)
at org.testng.SuiteRunnerWorker.run(SuiteRunnerWorker.java:96)
at org.testng.TestNG.runSuitesSequentially(TestNG.java:1218)
at org.testng.TestNG.runSuitesLocally(TestNG.java:1140)
at org.testng.TestNG.runSuites(TestNG.java:1069)
at org.testng.TestNG.run(TestNG.java:1037)
at org.testng.remote.AbstractRemoteTestNG.run(AbstractRemoteTestNG.java:115)
at org.testng.remote.RemoteTestNG.initAndRun(RemoteTestNG.java:251)
at org.testng.remote.RemoteTestNG.main(RemoteTestNG.java:77)
Caused by: java.lang.ArithmeticException: / by zero
at com.TestNG_TDD.expectedexcep.demo1(expectedexcep.java:16)
at java.base/jdk.internal.reflect.NativeMethodAccessorImpl.invoke0(Native Method)
at java.base/jdk.internal.reflect.NativeMethodAccessorImpl.invoke(NativeMethodAccessorImpl.java:64)
at java.base/jdk.internal.reflect.DelegatingMethodAccessorImpl.invoke(DelegatingMethodAccessorImpl.java:43)
at java.base/java.lang.reflect.Method.invoke(Method.java:564)
at org.testng.internal.MethodInvocationHelper.invokeMethod(MethodInvocationHelper.java:132)
at org.testng.internal.TestInvoker.invokeMethod(TestInvoker.java:599)
... 22 more
]]>
    </error>
  </testcase> <!-- demo1 -->
  <system-out/>
  <testcase classname="com.TestNG_TDD.expectedexcep" name="demo" time="0.009">
    <error message="
Method expectedexcep.demo()[pri:0, instance:com.TestNG_TDD.expectedexcep@36b4fe2a] should have thrown an exception of type class java.lang.ArithmeticException" type="org.testng.TestException">
      <![CDATA[org.testng.TestException: 
Method expectedexcep.demo()[pri:0, instance:com.TestNG_TDD.expectedexcep@36b4fe2a] should have thrown an exception of type class java.lang.ArithmeticException
at org.testng.internal.ExpectedExceptionsHolder.noException(ExpectedExceptionsHolder.java:82)
at org.testng.internal.TestInvoker.considerExceptions(TestInvoker.java:747)
at org.testng.internal.TestInvoker.invokeMethod(TestInvoker.java:635)
at org.testng.internal.TestInvoker.invokeTestMethod(TestInvoker.java:174)
at org.testng.internal.MethodRunner.runInSequence(MethodRunner.java:46)
at org.testng.internal.TestInvoker$MethodInvocationAgent.invoke(TestInvoker.java:822)
at org.testng.internal.TestInvoker.invokeTestMethods(TestInvoker.java:147)
at org.testng.internal.TestMethodWorker.invokeTestMethods(TestMethodWorker.java:146)
at org.testng.internal.TestMethodWorker.run(TestMethodWorker.java:128)
at java.base/java.util.ArrayList.forEach(ArrayList.java:1511)
at org.testng.TestRunner.privateRun(TestRunner.java:764)
at org.testng.TestRunner.run(TestRunner.java:585)
at org.testng.SuiteRunner.runTest(SuiteRunner.java:384)
at org.testng.SuiteRunner.runSequentially(SuiteRunner.java:378)
at org.testng.SuiteRunner.privateRun(SuiteRunner.java:337)
at org.testng.SuiteRunner.run(SuiteRunner.java:286)
at org.testng.SuiteRunnerWorker.runSuite(SuiteRunnerWorker.java:53)
at org.testng.SuiteRunnerWorker.run(SuiteRunnerWorker.java:96)
at org.testng.TestNG.runSuitesSequentially(TestNG.java:1218)
at org.testng.TestNG.runSuitesLocally(TestNG.java:1140)
at org.testng.TestNG.runSuites(TestNG.java:1069)
at org.testng.TestNG.run(TestNG.java:1037)
at org.testng.remote.AbstractRemoteTestNG.run(AbstractRemoteTestNG.java:115)
at org.testng.remote.RemoteTestNG.initAndRun(RemoteTestNG.java:251)
at org.testng.remote.RemoteTestNG.main(RemoteTestNG.java:77)
]]>
    </error>
  </testcase> <!-- demo -->
  <system-out/>
</testsuite> <!-- com.TestNG_TDD.expectedexcep -->
